Workbook

Sheet Stock y Compras
A1: RUBRO | B1: BIEN | C1: ORDEN DE COMPRA | D1: CATALOGO | E1: RENGLÓN | F1: CANTIDAD COMPRADA | G1: PRECIO UNITARIO | H1: PRECIO TOTAL | I1: BIENES EN STOCK | J1: SALDO EN $
A2: INSUMOS AIRES | B2: EQUIPO SPLIT DE 4500 FRIGORÍAS - TIPO DE CLIMATIZACIÓNFRIO/CALOR - EFICIENCIA ENERGÉTICA DE CLASE C O MAYOR | C2: 81-0080-OC24 | D2: 4.3.7-1367.320 | E2: 1 | F2: 13 | G2: 907100 | H2: =F2*G2 -> 11792300 | I2: =F2-SUMIFS(Pedidos!G:G, Pedidos!D:D, C2, Pedidos!E:E, E2, Pedidos!F:F, B2) -> 8 | J2: =I2*G2 -> 7256800
A3: INSUMOS AIRES | B3: EQUIPO SPLIT DE 6000 FRIGORÍAS - TIPO DE CLIMATIZACIÓN FRIO/CALOR - EFICIENCIA ENERGÉTICA DE CLASE C O MAYOR EN CALEFACCIÓN Y A EN REFRIGERACIÓN - NO CONVERTER | C3: 81-0081-OC24 | D3: 4.3.7-1367.330 | E3: 2 | F3: 11 | G3: 1413000 | H3: =F3*G3 -> 15543000 | I3: =F3-SUMIFS(Pedidos!G:G, Pedidos!D:D, C3, Pedidos!E:E, E3, Pedidos!F:F, B3) -> 4 | J3: =I3*G3 -> 5652000
A4: INSUMOS AIRES | B4: ROLLO DE 15 METROS CAÑO DE COBRE DE 5/8 | C4: 81-0082-OC24 | D4: 2.9.6-5591.3 | E4: 3 | F4: 4 | G4: 201000 | H4: =F4*G4 -> 804000 | I4: =F4-SUMIFS(Pedidos!G:G, Pedidos!D:D, C4, Pedidos!E:E, E4, Pedidos!F:F, B4) -> 2 | J4: =I4*G4 -> 402000
A5: INSUMOS AIRES | B5: ROLLO DE 15 METROS CAÑO DE COBRE DE 3/8 | C5: 81-0082-OC24 | D5: 2.9.6-5591.4 | E5: 4 | F5: 4 | G5: 112000 | H5: =F5*G5 -> 448000 | I5: =F5-SUMIFS(Pedidos!G:G, Pedidos!D:D, C5, Pedidos!E:E, E5, Pedidos!F:F, B5) -> 4 | J5: =I5*G5 -> 448000
A6: INSUMOS AIRES | B6: ROLLO DE 15 METROS CAÑO DE COBRE DE 1/2 | C6: 81-0082-OC24 | D6: 2.9.6-5591.5 | E6: 5 | F6: 5 | G6: 157000 | H6: =F6*G6 -> 785000 | I6: =F6-SUMIFS(Pedidos!G:G, Pedidos!D:D, C6, Pedidos!E:E, E6, Pedidos!F:F, B6) -> 2 | J6: =I6*G6 -> 314000
A7: INSUMOS AIRES | B7: ROLLO DE 15 METROS CAÑO DE COBRE DE 1/4 | C7: 81-0082-OC24 | D7: 2.9.6-5591.6 | E7: 6 | F7: 5 | G7: 73000 | H7: =F7*G7 -> 365000 | I7: =F7-SUMIFS(Pedidos!G:G, Pedidos!D:D, C7, Pedidos!E:E, E7, Pedidos!F:F, B7) -> 0 | J7: =I7*G7 -> 0
A8: INSUMOS AIRES | B8: ROLLO DE 2 METROS DE TIRA DE AISLACIÓN TÉRMICA PARA CAÑOS DE 5/8 | C8: 81-0082-OC24 | D8: 2.9.6-1712.305 | E8: 7 | F8: 33 | G8: 2990 | H8: =F8*G8 -> 98670 | I8: =F8-SUMIFS(Pedidos!G:G, Pedidos!D:D, C8, Pedidos!E:E, E8, Pedidos!F:F, B8) -> 17 | J8: =I8*G8 -> 50830
A9: INSUMOS AIRES | B9: ROLLO DE 2 METROS DE TIRA DE AISLACIÓN TÉRMICA PARA CAÑOS DE 3/8 | C9: 81-0082-OC24 | D9: 2.9.6-1712.306 | E9: 8 | F9: 33 | G9: 2300 | H9: =F9*G9 -> 75900 | I9: =F9-SUMIFS(Pedidos!G:G, Pedidos!D:D, C9, Pedidos!E:E, E9, Pedidos!F:F, B9) -> 24 | J9: =I9*G9 -> 55200
A10: INSUMOS AIRES | B10: ROLLO DE 2 METROS DE TIRA DE AISLACIÓN TÉRMICA PARA CAÑOS DE 1/2 | C10: 81-0082-OC24 | D10: 2.9.6-1712.307 | E10: 9 | F10: 42 | G10: 2590 | H10: =F10*G10 -> 108780 | I10: =F10-SUMIFS(Pedidos!G:G, Pedidos!D:D, C10, Pedidos!E:E, E10, Pedidos!F:F, B10) -> 22 | J10: =I10*G10 -> 56980
A11: INSUMOS AIRES | B11: ROLLO DE 2 METROS DE TIRA DE AISLACIÓN TÉRMICA PARA CAÑOS DE 1/4 | C11: 81-0082-OC24 | D11: 2.9.6-1712.308 | E11: 10 | F11: 42 | G11: 1630 | H11: =F11*G11 -> 68460 | I11: =F11-SUMIFS(Pedidos!G:G, Pedidos!D:D, C11, Pedidos!E:E, E11, Pedidos!F:F, B11) -> 13 | J11: =I11*G11 -> 21190
A12: INSUMOS AIRES | B12: CINTA DE PVC PARA REFRIGERACIÓN, SIN ADHESIVO – ROLLO DE 20 METROS | C12: 81-0082-OC24 | D12: 2.9.9-3027.9 | E12: 11 | F12: 24 | G12: 4000 | H12: =F12*G12 -> 96000 | I12: =F12-SUMIFS(Pedidos!G:G, Pedidos!D:D, C12, Pedidos!E:E, E12, Pedidos!F:F, B12) -> 5 | J12: =I12*G12 -> 20000
A13: INSUMOS AIRES | B13: MENSULAS PARA AIRE ACONDICIONADO DE 4500 A 6000 FRIGORIAS, 50X50 APROXIMADAMENTE | C13: 81-0082-OC24 | D13: 2.9.6-1376.235 | E13: 13 | F13: 24 | G13: 19200 | H13: =F13*G13 -> 460800 | I13: =F13-SUMIFS(Pedidos!G:G, Pedidos!D:D, C13, Pedidos!E:E, E13, Pedidos!F:F, B13) -> 21 | J13: =I13*G13 -> 403200
... A15: INSUMOS AIRES | B15: GARRAFA REFRIGERANTE R22 | C15: 81-0082-OC24 | D15: 2.5.6-6856.1 | E15: 15 | F15: 6 | G15: 440235 | H15: =F15*G15 -> 2641410 | I15: =F15-SUMIFS(Pedidos!G:G, Pedidos!D:D, C15, Pedidos!E:E, E15, Pedidos!F:F, B15) -> 5 | J15: =I15*G15 -> 2201175
A16: INSUMOS AIRES | B16: MANGUERA CRISTAL PARA DESAGÜE DE 5/8" – ROLLO DE 50 METROS (PRECIO POR METRO) | C16: 81-0082-OC24 | D16: 2.9.9-9053.30 | E16: 16 | F16: 150 | G16: =62000/50 -> 1240 | H16: =F16*G16 -> 186000 | I16: =F16-SUMIFS(Pedidos!G:G, Pedidos!D:D, C16, Pedidos!E:E, E16, Pedidos!F:F, B16) -> 125 | J16: =I16*G16 -> 155000
A17: INSUMOS AIRES | B17: TACO DE GOMA, AMORTIGUADOR ANTIVIBRACIÓN – BOLSA X 4 UNIDADES | C17: 81-0082-OC24 | D17: 2.9.6-1712.93 | E17: 17 | F17: 24 | G17: 2850 | H17: =F17*G17 -> 68400 | I17: =F17-SUMIFS(Pedidos!G:G, Pedidos!D:D, C17, Pedidos!E:E, E17, Pedidos!F:F, B17) -> 13 | J17: =I17*G17 -> 37050
A18: INSUMOS AIRES | B18: CAJA DE 200 TARUGOS MULTIPROPÓSITOS DE 8MM | C18: 81-0082-OC24 | D18: 2.5.8-819.9 | E18: 18 | F18: =7*200 -> 1400 | G18: =6400/200 -> 32 | H18: =F18*G18 -> 44800 | I18: =F18-SUMIFS(Pedidos!G:G, Pedidos!D:D, C18, Pedidos!E:E, E18, Pedidos!F:F, B18) -> 1160 | J18: =I18*G18 -> 37120
A19: INSUMOS AIRES | B19: CAJA DE 200 TARUGOS MULTIPROPÓSITOS DE 10MM | C19: 81-0082-OC24 | D19: 2.5.8-819.9 | E19: 19 | F19: =7*200 -> 1400 | G19: =13500/200 -> 67.5 | H19: =F19*G19 -> 94500 | I19: =F19-SUMIFS(Pedidos!G:G, Pedidos!D:D, C19, Pedidos!E:E, E19, Pedidos!F:F, B19) -> 1224 | J19: =I19*G19 -> 82620
A20: INSUMOS AIRES | B20: CAJA DE 200 TORNILLOS TIRAFONDO PARA TARUGO DE 10MM - PRECIO POR UNIDAD | C20: 81-0082-OC24 | D20: 2.7.9-643.112 | E20: 20 | F20: 1400 | G20: =23350/200 -> 116.75 | H20: =F20*G20 -> 163450 | I20: =F20-SUMIFS(Pedidos!G:G, Pedidos!D:D, C20, Pedidos!E:E, E20, Pedidos!F:F, B20) -> 1224 | J20: =I20*G20 -> 142902
A21: INSUMOS AIRES | B21: CAJA DE 200 TORNILLOS TIRAFONDO PARA TARUGO DE 8MM | C21: 81-0082-OC24 | D21: 2.7.9-643.25 | E21: 21 | F21: 1400 | G21: =15400/200 -> 77 | H21: =F21*G21 -> 107800 | I21: =F21-SUMIFS(Pedidos!G:G, Pedidos!D:D, C21, Pedidos!E:E, E21, Pedidos!F:F, B21) -> 1160 | J21: =I21*G21 -> 89320
A22: INSUMOS AIRES | B22: CAJA DE 200 ARANDELAS PLANAS PARA TARUGOS DE 10MM | C22: 81-0082-OC24 | D22: 2.7.9-1600.44 | E22: 22 | F22: =7*200 -> 1400 | G22: =8900/200 -> 44.5 | H22: =F22*G22 -> 62300 | I22: =F22-SUMIFS(Pedidos!G:G, Pedidos!D:D, C22, Pedidos!E:E, E22, Pedidos!F:F, B22) -> 1224 | J22: =I22*G22 -> 54468
A23: INSUMOS AIRES | B23: CAJA DE 200 ARANDELAS PLANAS PARA TARUGOS DE 8MM | C23: 81-0082-OC24 | D23: 2.7.9-1600.35 | E23: 23 | F23: =7*200 -> 1400 | G23: =6000/200 -> 30 | H23: =F23*G23 -> 42000 | I23: =F23-SUMIFS(Pedidos!G:G, Pedidos!D:D, C23, Pedidos!E:E, E23, Pedidos!F:F, B23) -> 1160 | J23: =I23*G23 -> 34800
A24: PLOMERIA | B24: ADHESIVO - CEMENTO DE CONTACTO; TIPO: DE CONTACTO, PRESENTACION: ENVASE X 1 L | C24: 81-0054-OC24 | D24: 2.5.9-6887.43 | E24: 19 | F24: 10 | G24: 10500 | H24: =F24*G24 -> 105000 | I24: =F24-SUMIFS(Pedidos!G:G, Pedidos!D:D, C24, Pedidos!E:E, E24, Pedidos!F:F, B24) -> 6 | J24: =I24*G24 -> 63000
A25: PLOMERIA | B25: ADHESIVO COLA CARPINTERO BLANCO | C25: EXISTENCIA PREV. 1 | E25: S/N | F25: 1 | G25: 73 | H25: =F25*G25 -> 73 | I25: =F25-SUMIFS(Pedidos!G:G, Pedidos!D:D, C25, Pedidos!E:E, E25, Pedidos!F:F, B25) -> 1 | J25: =I25*G25 -> 73
A26: PLOMERIA | B26: ARANDELA PLASTICA 1/2" | C26: EXISTENCIA PREV. 1 | D26: 2.5.8-6723.1 | E26: S/N | F26: 27 | G26: 1.2 | H26: =F26*G26 -> 32.4 | I26: =F26-SUMIFS(Pedidos!G:G, Pedidos!D:D, C26, Pedidos!E:E, E26, Pedidos!F:F, B26) -> 27 | J26: =I26*G26 -> 32.4
A27: PLOMERIA | B27: ARANDELA PLASTICA 3/4" | C27: EXISTENCIA PREV. 1 | D27: 2.5.8-6723.2 | E27: S/N | F27: 9 | G27: 0.5 | H27: =F27*G27 -> 4.5 | I27: =F27-SUMIFS(Pedidos!G:G, Pedidos!D:D, C27, Pedidos!E:E, E27, Pedidos!F:F, B27) -> 9 | J27: =I27*G27 -> 4.5
A28: PLOMERIA | B28: ARANDELA PLASTICA 3/4" | C28: EXISTENCIA PREV. 2 | D28: 2.5.8-6723.2 | E28: S/N | F28: 52 | G28: 1.5 | H28: =F28*G28 -> 78 | I28: =F28-SUMIFS(Pedidos!G:G, Pedidos!D:D, C28, Pedidos!E:E, E28, Pedidos!F:F, B28) -> 52 | J28: =I28*G28 -> 78
A29: PLOMERIA | B29: ARO GOMA BASE DE INODORO | C29: 81-0049-OC24 | D29: 2.9.6-5017.22 | E29: 8 | F29: 100 | G29: 1234.2 | H29: =F29*G29 -> 123420 | I29: =F29-SUMIFS(Pedidos!G:G, Pedidos!D:D, C29, Pedidos!E:E, E29, Pedidos!F:F, B29) -> 100 | J29: =I29*G29 -> 123420
A30: PLOMERIA | B30: BOYA OBTURADOR UNIVERSAL REGULABLE PARA DEPOSITO EMBUTIR TIPO IDEAL 1450 | C30: 81-0049-OC24 | D30: 2.9.6-5017.6 | E30: 5 | F30: 50 | G30: 2912.71 | H30: =F30*G30 -> 145635.5 | I30: =F30-SUMIFS(Pedidos!G:G, Pedidos!D:D, C30, Pedidos!E:E, E30, Pedidos!F:F, B30) -> 46 | J30: =I30*G30 -> 133984.66
A31: PLOMERIA | B31: BOYAS FLOTANTE telgopor | C31: EXISTENCIA PREV. 1 | D31: 2.9.6-402.1 | E31: S/N | F31: 5 | G31: 11 | H31: =F31*G31 -> 55 | I31: =F31-SUMIFS(Pedidos!G:G, Pedidos!D:D, C31, Pedidos!E:E, E31, Pedidos!F:F, B31) -> 5 | J31: =I31*G31 -> 55
A32: PLOMERIA | B32: BOYAS FLOTANTE telgopor | C32: EXISTENCIA PREV. 2 | D32: 2.9.6-402.1 | E32: S/N | F32: 14 | G32: 22.02 | H32: =F32*G32 -> 308.28 | I32: =F32-SUMIFS(Pedidos!G:G, Pedidos!D:D, C32, Pedidos!E:E, E32, Pedidos!F:F, B32) -> 14 | J32: =I32*G32 -> 308.28
A33: PLOMERIA | B33: BOTON PULSADO MOCHILA LATERAL | C33: EXISTENCIA PREV. 1 | E33: S/N | F33: 11 | G33: 66 | H33: =F33*G33 -> 726 | I33: =F33-SUMIFS(Pedidos!G:G, Pedidos!D:D, C33, Pedidos!E:E, E33, Pedidos!F:F, B33) -> 11 | J33: =I33*G33 -> 726
A34: PLOMERIA | B34: BOTON PARA MOCHILA CUADRADO PLASTICO | C34: EXISTENCIA PREV. 1 | E34: S/N | F34: 12 | G34: 198 | H34: =F34*G34 -> 2376 | I34: =F34-SUMIFS(Pedidos!G:G, Pedidos!D:D, C34, Pedidos!E:E, E34, Pedidos!F:F, B34) -> 12 | J34: =I34*G34 -> 2376
A35: PLOMERIA | B35: BOTON PULSADOR MOCHILA SUPERIOR REDONDO | C35: EXISTENCIA PREV. 1 | E35: S/N | F35: 9 | G35: 57 | H35: =F35*G35 -> 513 | I35: =F35-SUMIFS(Pedidos!G:G, Pedidos!D:D, C35, Pedidos!E:E, E35, Pedidos!F:F, B35) -> 9 | J35: =I35*G35 -> 513
A36: PLOMERIA | B36: BUJE BRONCE REDUCCION DIAMETRO MAYOR 1/4" | C36: EXISTENCIA PREV. 1 | D36: 2.5.8-3536.11 | E36: S/N | F36: 21 | G36: 0.43 | H36: =F36*G36 -> 9.03 | I36: =F36-SUMIFS(Pedidos!G:G, Pedidos!D:D, C36, Pedidos!E:E, E36, Pedidos!F:F, B36) -> 21 | J36: =I36*G36 -> 9.03
A37: PLOMERIA | B37: BUJE BRONCE REDUCCION DIAMETRO MAYOR 3/8" | C37: EXISTENCIA PREV. 1 | D37: 2.5.8-3536.5 | E37: S/N | F37: 22 | G37: 0.6 | H37: =F37*G37 -> 13.2 | I37: =F37-SUMIFS(Pedidos!G:G, Pedidos!D:D, C37, Pedidos!E:E, E37, Pedidos!F:F, B37) -> 22 | J37: =I37*G37 -> 13.2
A38: PLOMERIA | B38: BUJE BRONCE REDUCCION 1/2" M A 3/8" PESTAÑA | C38: EXISTENCIA PREV. 1 | D38: 2.5.8-3536.5 | E38: S/N | F38: 20 | G38: 0.85 | H38: =F38*G38 -> 17 | I38: =F38-SUMIFS(Pedidos!G:G, Pedidos!D:D, C38, Pedidos!E:E, E38, Pedidos!F:F, B38) -> 20 | J38: =I38*G38 -> 17
A39: PLOMERIA | B39: BUJE HIDROBRONZ REDUCCION 1/2" A 3/8" | C39: EXISTENCIA PREV. 1 | D39: 2.5.8-3536.6 | E39: S/N | F39: 3 | G39: 0.73 | H39: =F39*G39 -> 2.19 | I39: =F39-SUMIFS(Pedidos!G:G, Pedidos!D:D, C39, Pedidos!E:E, E39, Pedidos!F:F, B39) -> 3 | J39: =I39*G39 -> 2.19
A40: PLOMERIA | B40: BUJE HIDROBRONZ REDUCCION 1" A 3/4" | C40: EXISTENCIA PREV. 1 | D40: 2.5.8-3536.4 | E40: S/N | F40: 19 | G40: 1.37 | H40: =F40*G40 -> 26.03 | I40: =F40-SUMIFS(Pedidos!G:G, Pedidos!D:D, C40, Pedidos!E:E, E40, Pedidos!F:F, B40) -> 19 | J40: =I40*G40 -> 26.03
A41: PLOMERIA | B41: CAÑAMO BOLSA X 100 GR | C41: EXISTENCIA PREV. 1 | E41: S/N | F41: 10 | G41: 7.1 | H41: =F41*G41 -> 71 | I41: =F41-SUMIFS(Pedidos!G:G, Pedidos!D:D, C41, Pedidos!E:E, E41, Pedidos!F:F, B41) -> 10 | J41: =I41*G41 -> 71
...

Sheet Pedidos
A1: N° DE PEDIDO | B1: FECHA DE ENTREGA | C1: DEPENDENCIA | D1: ORDEN DE COMPRA | E1: RENGLÓN | F1: BIEN | G1: CANTIDAD ENTREGADA | H1: RUBRO
D2: 81-0080-OC24 | E2: 1 | F2: EQUIPO SPLIT DE 4500 FRIGORÍAS - TIPO DE CLIMATIZACIÓNFRIO/CALOR - EFICIENCIA ENERGÉTICA DE CLASE C O MAYOR | G2: 2
D3: 81-0081-OC24 | E3: 2 | F3: EQUIPO SPLIT DE 6000 FRIGORÍAS - TIPO DE CLIMATIZACIÓN FRIO/CALOR - EFICIENCIA ENERGÉTICA DE CLASE C O MAYOR EN CALEFACCIÓN Y A EN REFRIGERACIÓN - NO CONVERTER | G3: 3
D4: 81-0082-OC24 | E4: 9 | F4: ROLLO DE 2 METROS DE TIRA DE AISLACIÓN TÉRMICA PARA CAÑOS DE 1/2 | G4: 2
D5: 81-0082-OC24 | E5: 10 | F5: ROLLO DE 2 METROS DE TIRA DE AISLACIÓN TÉRMICA PARA CAÑOS DE 1/4 | G5: 4
D6: 81-0082-OC24 | E6: 11 | F6: CINTA DE PVC PARA REFRIGERACIÓN, SIN ADHESIVO – ROLLO DE 20 METROS | G6: 2
D7: 81-0082-OC24 | E7: 13 | F7: MENSULAS PARA AIRE ACONDICIONADO DE 4500 A 6000 FRIGORIAS, 50X50 APROXIMADAMENTE | G7: 1
D8: 81-0082-OC24 | E8: 14 | F8: GARRAFA REFRIGERANTE R410 | G8: 1
D9: 81-0082-OC24 | E9: 15 | F9: GARRAFA REFRIGERANTE R22 | G9: 1
D10: 81-0082-OC24 | E10: 16 | F10: MANGUERA CRISTAL PARA DESAGÜE DE 5/8" – ROLLO DE 50 METROS (PRECIO POR METRO) | G10: 25
D11: 81-0082-OC24 | E11: 17 | F11: TACO DE GOMA, AMORTIGUADOR ANTIVIBRACIÓN – BOLSA X 4 UNIDADES | G11: 1
D12: 81-0082-OC24 | E12: 20 | F12: CAJA DE 200 TORNILLOS TIRAFONDO PARA TARUGO DE 10MM - PRECIO POR UNIDAD | G12: 8
D13: 81-0082-OC24 | E13: 21 | F13: CAJA DE 200 TORNILLOS TIRAFONDO PARA TARUGO DE 8MM | G13: 16
... D77: 81-0059-OC24 | E77: 25 | F77: Conductor tipo taller - 3 x 2,5 mm2 - aislación PVC, normalizado Tipo Pirelli o superior x 100 mts. (PRECIO POR METRO) | G77: 100
D78: EXISTENCIA PREV. 1 | E78: S/N | F78: Panel Plafón Led Embutir 60x60 cm Cuadrado 40w Luz Fría Empotrable | G78: 1
D79: 81-0057-OC24 | E79: 23 | F79: Pinza amperométrica digital Uni-T UT204+ 600ª | G79: 1
D80: EXISTENCIA PREV. 1 | E80: S/N | F80: MODULO TOMA CORRIENTE DE 10 Amp | G80: 16
D81: 81-0058-OC24 | E81: 9 | F81: Módulo 1 toma para embutir - 10 A - Tipo línea Siglo XXI | G81: 16
D82: 81-0058-OC24 | E82: 12 | F82: Módulo punto simple – Tipo Jeluz platinum | G82: 27
D83: 81-0058-OC24 | E83: 11 | F83: Tapa rectangular - Tipo Jeluz platinum | G83: 11
D84: 81-0058-OC24 | E84: 10 | F84: Bastidor rectangular – Tipo Jeluz | G84: 13
D85: 81-0057-OC24 | E85: 3 | F85: Lampara Dicroica Led 7w Gu10 220v Gu 10 - luz fría | G85: 10
D86: 81-0059-OC24 | E86: 25 | F86: Conductor tipo taller - 3 x 2,5 mm2 - aislación PVC, normalizado Tipo Pirelli o superior x 100 mts. (PRECIO POR METRO) | G86: 100
D87: EXISTENCIA PREV. 1 | E87: S/N | F87: SOPORTE LISTON PARA 2 TUBOS | G87: 16
D88: EXISTENCIA PREV. 2 | E88: S/N | F88: SOPORTE LISTON PARA 2 TUBOS | G88: 6
D89: 81-0057-OC24 | E89: 1 | F89: Tubo led 18w T8 220v (reemplazo flurescente 36w) 120 cm - luz fría | G89: 100
D90: 81-0051-OC24 | E90: 32 | F90: Válvula Automática + Tecla De Descarga – Clean- Combo Deca | G90: 4
D91: 81-0058-OC24 | E91: 14 | F91: Zapatilla 4 tomas con cable 2,5 / 3 mts. - con llave de corte (Tipo Kalop, Richi, Cambre o calidad superior) | G91: 11
D92: EXISTENCIA PREV. 1 | E92: S/N | F92: GOMA FUELLE P/ INODORO CORTAS | G92: 2
D93: EXISTENCIA PREV. 1 | E93: S/N | F93: GOMA FUELLE PARA INODORO (LARGO) | G93: 3
D94: 81-0054-OC24 | E94: 26 | F94: TORNILLOS FIX CABEZA FRESADA RANURA PHILLIPS ACABADO ZINCADO AMARILLO 6 X 60 MM | G94: 20
D95: 81-0054-OC24 | E95: 24 | F95: TORNILLOS FIX CABEZA FRESADA RANURA PHILLIPS ACABADO ZINCADO AMARILLO 4 X 35 MM | G95: 40
D96: 81-0050-OC24 | E96: 12 | F96: SELLADOR DE ROSCAS SANITARIAS CAUCHO X 125 CC TIPO HYDRO 3 | G96: 5
D97: 81-0049-OC24 | E97: 1 | F97: CONEXIONES P/ SANITARIOS; TIPO FLEXIBLE MALLADO - MATERAIL ACERO INOXIDABLE - GOMA - LONG. DE CUERPO 40 CM - TIPO DE CONEXIÓN 1/2 PULGADAS | G97: 6
D98: 81-0054-OC24 | E98: 19 | F98: ADHESIVO - CEMENTO DE CONTACTO; TIPO: DE CONTACTO, PRESENTACION: ENVASE X 1 L | G98: 2
D99: 81-0054-OC24 | E99: 15 | F99: CANILLA LAVATORIO AUTOMATICA TEMPORIZADA A PRESION TIPO FV; PAZZA; GENEBRE O CALIDAD SUPERIOR. LARGO CANILLA 10 CM (+/- 10%), ALTURA CANILLA 10 CM (+/- 20%) | G99: 8
D100: 81-0052-OC24 | E100: 31 | F100: Descarga Mochila Capea Roca Superior Cromado Repuesto Eco Flush | G100: 3
D101: 81-0049-OC24 | E101: 5 | F101: BOYA OBTURADOR UNIVERSAL REGULABLE PARA DEPOSITO EMBUTIR TIPO IDEAL 1450 | G101: 2
D102: 81-0047-OC24 | E102: 10 | F102: Diluyente - Envase x 4L | G102: 4
D103: 81-0047-OC24 | E103: 15 | F103: Pincel cerda larga N° 20 | G103: 12
...

Sheet Consolidado
A1: CONSOLIDADO DE STOCK Y SALDO
A2: ORDEN DE COMPRA | B2: (Varios elementos)
A3: PRECIO TOTAL | B3: 11792300 | E3: ORDEN DE COMPRA | F3: (Varios elementos)
B5: SUM of PRECIO TOTAL | E5: ABROCHADORA 10/50 pinza | F5: SUM of CANTIDAD COMPRADA | G5: 67
A6: EQUIPO SPLIT DE 4500 FRIGORÍAS - TIPO DE CLIMATIZACIÓNFRIO/CALOR - EFICIENCIA ENERGÉTICA DE CLASE C O MAYOR | B6: 11792300 | F6: SUM of BIENES EN STOCK | G6: 58
A7: Total general | B7: 11792300 | E7: ABROCHADORA 21/6 pinza | F7: SUM of CANTIDAD COMPRADA | G7: 64
F8: SUM of BIENES EN STOCK | G8: 59
E9: ABROCHADORA ESCRITORIO 64 | F9: SUM of CANTIDAD COMPRADA | G9: 74
F10: SUM of BIENES EN STOCK | G10: 60
E11: ABROCHADORA N°23 pinza | F11: SUM of CANTIDAD COMPRADA | G11: 4
F12: SUM of BIENES EN STOCK | G12: 4
E13: ACOPLE RECTO 10 X 20 | F13: SUM of CANTIDAD COMPRADA | G13: 96
F14: SUM of BIENES EN STOCK | G14: 96
E15: ACOPLE RECTO 40 X 16 | F15: SUM of CANTIDAD COMPRADA | G15: 93
F16: SUM of BIENES EN STOCK | G16: 93
E17: ADAPTADOR DE 2 REDONDO A 2 PLANO | F17: SUM of CANTIDAD COMPRADA | G17: 15
F18: SUM of BIENES EN STOCK | G18: 15
E19: ADAPTADOR DE 3 PLANO A 2 REDONDO | F19: SUM of CANTIDAD COMPRADA | G19: 29
F20: SUM of BIENES EN STOCK | G20: 29
E21: ADHESIVO - CEMENTO DE CONTACTO; TIPO: DE CONTACTO, PRESENTACION: ENVASE X 1 L | F21: SUM of CANTIDAD COMPRADA | G21: 10
F22: SUM of BIENES EN STOCK | G22: 6
E23: ADHESIVO BARRA | F23: SUM of CANTIDAD COMPRADA | G23: 325
F24: SUM of BIENES EN STOCK | G24: 304
E25: ADHESIVO COLA CARPINTERO BLANCO | F25: SUM of CANTIDAD COMPRADA | G25: 1
F26: SUM of BIENES EN STOCK | G26: 1
E27: Adhesivo tipo boligoma x 30 ml. | F27: SUM of CANTIDAD COMPRADA | G27: 100
F28: SUM of BIENES EN STOCK | G28: 100
E29: ADHESIVO TRANSPARENTE X50 ML | F29: SUM of CANTIDAD COMPRADA | G29: 94
F30: SUM of BIENES EN STOCK | G30: 70
E31: ADHESIVO VINILICO X 250 CC | F31: SUM of CANTIDAD COMPRADA | G31: 117
F32: SUM of BIENES EN STOCK | G32: 94
E33: ADHESIVO VINILICO X 30 ML | F33: SUM of CANTIDAD COMPRADA | G33: 281
F34: SUM of BIENES EN STOCK | G34: 238
E35: ALMOHADILLA PARA SELLOS | F35: SUM of CANTIDAD COMPRADA | G35: 41
F36: SUM of BIENES EN STOCK | G36: 41
E37: AMOLADORA ANGULAR DE BANCO 150 MM 250 WATTS | F37: SUM of CANTIDAD COMPRADA | G37: 2
F38: SUM of BIENES EN STOCK | G38: 2
E39: ARANDELA PLASTICA 1/2" | F39: SUM of CANTIDAD COMPRADA | G39: 27
F40: SUM of BIENES EN STOCK | G40: 27
E41: ARANDELA PLASTICA 3/4" | F41: SUM of CANTIDAD COMPRADA | G41: 61
...

Sheet CIERRE POR RUBRO
C3: SUM of BIENES EN STOCK
A4: CABLE CANAL | C4: 791
A5: ELECTRICIDAD | C5: 30697
A6: INSUMOS AIRES | C6: 7422
A7: LIBRERIA | C7: 123957
A8: PINTURA | C8: 2879
A9: PLOMERIA | C9: 12311
A10: TERMOFUSION | C10: 869
A11: VARIOS | C11: 37
A12: VESTIMENTA | C12: 1017
A13: Total general | C13: 179980
